<sdf version='1.7'>
  <world name='default'>
    <light name='sun' type='directional'>
      <cast_shadows>1</cast_shadows>
      <pose>0 0 10 0 -0 0</pose>
      <diffuse>0.8 0.8 0.8 1</diffuse>
      <specular>0.2 0.2 0.2 1</specular>
      <attenuation>
        <range>1000</range>
        <constant>0.9</constant>
        <linear>0.01</linear>
        <quadratic>0.001</quadratic>
      </attenuation>
      <direction>-0.5 0.1 -0.9</direction>
      <spot>
        <inner_angle>0</inner_angle>
        <outer_angle>0</outer_angle>
        <falloff>0</falloff>
      </spot>
    </light>
    <model name='ground_plane'>
      <static>1</static>
      <link name='link'>
        <collision name='collision'>
          <geometry>
            <plane>
              <normal>0 0 1</normal>
              <size>100 100</size>
            </plane>
          </geometry>
          <surface>
            <contact>
              <collide_bitmask>65535</collide_bitmask>
              <ode/>
            </contact>
            <friction>
              <ode>
                <mu>100</mu>
                <mu2>50</mu2>
              </ode>
              <torsional>
                <ode/>
              </torsional>
            </friction>
            <bounce/>
          </surface>
          <max_contacts>10</max_contacts>
        </collision>
        <visual name='visual'>
          <cast_shadows>0</cast_shadows>
          <geometry>
            <plane>
              <normal>0 0 1</normal>
              <size>100 100</size>
            </plane>
          </geometry>
          <material>
            <script>
              <uri>file://media/materials/scripts/gazebo.material</uri>
              <name>Gazebo/Grey</name>
            </script>
          </material>
        </visual>
        <self_collide>0</self_collide>
        <enable_wind>0</enable_wind>
        <kinematic>0</kinematic>
      </link>
    </model>
    <gravity>0 0 -9.8</gravity>
    <magnetic_field>6e-06 2.3e-05 -4.2e-05</magnetic_field>
    <atmosphere type='adiabatic'/>
    <physics type='ode'>
      <max_step_size>0.001</max_step_size>
      <real_time_factor>1</real_time_factor>
      <real_time_update_rate>1000</real_time_update_rate>
    </physics>
    <scene>
      <ambient>0.4 0.4 0.4 1</ambient>
      <background>0.7 0.7 0.7 1</background>
      <shadows>1</shadows>
    </scene>
    <audio>
      <device>default</device>
    </audio>
    <wind/>
    <spherical_coordinates>
      <surface_model>EARTH_WGS84</surface_model>
      <latitude_deg>0</latitude_deg>
      <longitude_deg>0</longitude_deg>
      <elevation>0</elevation>
      <heading_deg>0</heading_deg>
    </spherical_coordinates>
    <model name='pynqcar'>
      <link name='base_link'>
        <inertial>
          <pose>0.021429 0 0.1 0 -0 0</pose>
          <mass>0.7</mass>
          <inertia>
            <ixx>0.00592333</ixx>
            <ixy>0</ixy>
            <ixz>0.00245</ixz>
            <iyy>0.0194294</iyy>
            <iyz>0</iyz>
            <izz>0.0213111</izz>
          </inertia>
        </inertial>
        <collision name='base_link_fixed_joint_lump__cat_head_link_collision'>
          <pose>0.25 0 0.03 3.14159 1.57079 3.14159</pose>
          <geometry>
            <cylinder>
              <length>0.01</length>
              <radius>0.06</radius>
            </cylinder>
          </geometry>
          <surface>
            <contact>
              <ode/>
            </contact>
            <friction>
              <ode/>
              <torsional>
                <ode/>
              </torsional>
            </friction>
            <bounce/>
          </surface>
          <max_contacts>10</max_contacts>
        </collision>
        <collision name='base_link_fixed_joint_lump__chassis_collision_1'>
          <pose>0 0 0.1 0 -0 0</pose>
          <geometry>
            <box>
              <size>0.5 0.3 0.15</size>
            </box>
          </geometry>
          <surface>
            <contact>
              <ode/>
            </contact>
            <friction>
              <ode/>
              <torsional>
                <ode/>
              </torsional>
            </friction>
            <bounce/>
          </surface>
          <max_contacts>10</max_contacts>
        </collision>
        <collision name='base_link_fixed_joint_lump__laser_frame_collision_2'>
          <pose>-0.1 0 0.17 0 -0 0</pose>
          <geometry>
            <cylinder>
              <length>0.04</length>
              <radius>0.05</radius>
            </cylinder>
          </geometry>
          <surface>
            <contact>
              <ode/>
            </contact>
            <friction>
              <ode/>
              <torsional>
                <ode/>
              </torsional>
            </friction>
            <bounce/>
          </surface>
          <max_contacts>10</max_contacts>
        </collision>
        <visual name='base_link_fixed_joint_lump__cat_head_link_visual'>
          <pose>0.25 0 0.03 3.14159 1.57079 3.14159</pose>
          <geometry>
            <cylinder>
              <length>0.01</length>
              <radius>0.06</radius>
            </cylinder>
          </geometry>
          <material>
            <script>
              <name>Gazebo/Blue</name>
              <uri>file://media/materials/scripts/gazebo.material</uri>
            </script>
          </material>
        </visual>
        <visual name='base_link_fixed_joint_lump__chassis_visual_1'>
          <pose>0 0 0.1 0 -0 0</pose>
          <geometry>
            <box>
              <size>0.5 0.3 0.15</size>
            </box>
          </geometry>
          <material>
            <script>
              <name>Gazebo/Orange</name>
              <uri>file://media/materials/scripts/gazebo.material</uri>
            </script>
          </material>
        </visual>
        <visual name='base_link_fixed_joint_lump__laser_frame_visual_2'>
          <pose>-0.1 0 0.17 0 -0 0</pose>
          <geometry>
            <cylinder>
              <length>0.04</length>
              <radius>0.05</radius>
            </cylinder>
          </geometry>
          <material>
            <script>
              <name>Gazebo/Red</name>
              <uri>file://media/materials/scripts/gazebo.material</uri>
            </script>
          </material>
        </visual>
        <sensor name='laser' type='ray'>
          <visualize>1</visualize>
          <update_rate>10</update_rate>
          <ray>
            <scan>
              <horizontal>
                <samples>360</samples>
                <min_angle>-3.14</min_angle>
                <max_angle>3.14</max_angle>
                <resolution>1</resolution>
              </horizontal>
              <vertical>
                <samples>1</samples>
                <min_angle>0</min_angle>
                <max_angle>0</max_angle>
              </vertical>
            </scan>
            <range>
              <min>0.3</min>
              <max>12</max>
            </range>
          </ray>
          <plugin name='laser_controller' filename='libgazebo_ros_ray_sensor.so'>
            <ros>
              <argument>~/out:=scan</argument>
            </ros>
            <output_type>sensor_msgs/LaserScan</output_type>
            <frame_name>laser_frame</frame_name>
          </plugin>
          <pose>-0.1 0 0.17 0 -0 0</pose>
        </sensor>
        <self_collide>0</self_collide>
        <enable_wind>0</enable_wind>
        <kinematic>0</kinematic>
      </link>
      <joint name='left_back_wheel_joint' type='revolute'>
        <pose relative_to='base_link'>-0.125 0.15 0 0 -0 0</pose>
        <parent>base_link</parent>
        <child>left_back_wheel_link</child>
        <axis>
          <xyz>0 1 0</xyz>
          <limit>
            <lower>-1e+16</lower>
            <upper>1e+16</upper>
          </limit>
          <dynamics>
            <spring_reference>0</spring_reference>
            <spring_stiffness>0</spring_stiffness>
          </dynamics>
        </axis>
      </joint>
      <link name='left_back_wheel_link'>
        <pose relative_to='left_back_wheel_joint'>0 0 0 0 -0 0</pose>
        <inertial>
          <pose>0 0 0 0 -0 0</pose>
          <mass>0.6</mass>
          <inertia>
            <ixx>0.0006</ixx>
            <ixy>0</ixy>
            <ixz>0</ixz>
            <iyy>0.0006</iyy>
            <iyz>0</iyz>
            <izz>0.0006</izz>
          </inertia>
        </inertial>
        <collision name='left_back_wheel_link_collision'>
          <pose>0 0 0 1.5708 -0 0</pose>
          <geometry>
            <cylinder>
              <length>0.04</length>
              <radius>0.05</radius>
            </cylinder>
          </geometry>
          <surface>
            <contact>
              <ode/>
            </contact>
            <friction>
              <ode>
                <mu>0.01</mu>
                <mu2>0.01</mu2>
              </ode>
              <torsional>
                <ode/>
              </torsional>
            </friction>
            <bounce/>
          </surface>
          <max_contacts>10</max_contacts>
        </collision>
        <visual name='left_back_wheel_link_visual'>
          <pose>0 0 0 1.5708 -0 0</pose>
          <geometry>
            <cylinder>
              <length>0.04</length>
              <radius>0.05</radius>
            </cylinder>
          </geometry>
          <material>
            <ambient>0.1764 0.4588 0.8509 1</ambient>
            <diffuse>0.1764 0.4588 0.8509 1</diffuse>
            <specular>0.1764 0.4588 0.8509 1</specular>
            <emissive>0 0 0 0</emissive>
            <script>
              <name>Gazebo/Black</name>
              <uri>file://media/materials/scripts/gazebo.material</uri>
            </script>
          </material>
        </visual>
        <self_collide>0</self_collide>
        <enable_wind>0</enable_wind>
        <kinematic>0</kinematic>
      </link>
      <joint name='left_front_wheel_joint' type='revolute'>
        <pose relative_to='base_link'>0.125 0.15 0 0 -0 0</pose>
        <parent>base_link</parent>
        <child>left_front_wheel_link</child>
        <axis>
          <xyz>0 1 0</xyz>
          <limit>
            <lower>-1e+16</lower>
            <upper>1e+16</upper>
          </limit>
          <dynamics>
            <spring_reference>0</spring_reference>
            <spring_stiffness>0</spring_stiffness>
          </dynamics>
        </axis>
      </joint>
      <link name='left_front_wheel_link'>
        <pose relative_to='left_front_wheel_joint'>0 0 0 0 -0 0</pose>
        <inertial>
          <pose>0 0 0 0 -0 0</pose>
          <mass>0.6</mass>
          <inertia>
            <ixx>0.0006</ixx>
            <ixy>0</ixy>
            <ixz>0</ixz>
            <iyy>0.0006</iyy>
            <iyz>0</iyz>
            <izz>0.0006</izz>
          </inertia>
        </inertial>
        <collision name='left_front_wheel_link_collision'>
          <pose>0 0 0 1.5708 -0 0</pose>
          <geometry>
            <cylinder>
              <length>0.04</length>
              <radius>0.05</radius>
            </cylinder>
          </geometry>
          <surface>
            <contact>
              <ode/>
            </contact>
            <friction>
              <ode>
                <mu>0.01</mu>
                <mu2>0.01</mu2>
              </ode>
              <torsional>
                <ode/>
              </torsional>
            </friction>
            <bounce/>
          </surface>
          <max_contacts>10</max_contacts>
        </collision>
        <visual name='left_front_wheel_link_visual'>
          <pose>0 0 0 1.5708 -0 0</pose>
          <geometry>
            <cylinder>
              <length>0.04</length>
              <radius>0.05</radius>
            </cylinder>
          </geometry>
          <material>
            <ambient>0.1764 0.4588 0.8509 1</ambient>
            <diffuse>0.1764 0.4588 0.8509 1</diffuse>
            <specular>0.1764 0.4588 0.8509 1</specular>
            <emissive>0 0 0 0</emissive>
            <script>
              <name>Gazebo/Black</name>
              <uri>file://media/materials/scripts/gazebo.material</uri>
            </script>
          </material>
        </visual>
        <self_collide>0</self_collide>
        <enable_wind>0</enable_wind>
        <kinematic>0</kinematic>
      </link>
      <joint name='right_back_wheel_joint' type='revolute'>
        <pose relative_to='base_link'>-0.125 -0.15 0 0 -0 0</pose>
        <parent>base_link</parent>
        <child>right_back_wheel_link</child>
        <axis>
          <xyz>0 1 0</xyz>
          <limit>
            <lower>-1e+16</lower>
            <upper>1e+16</upper>
          </limit>
          <dynamics>
            <spring_reference>0</spring_reference>
            <spring_stiffness>0</spring_stiffness>
          </dynamics>
        </axis>
      </joint>
      <link name='right_back_wheel_link'>
        <pose relative_to='right_back_wheel_joint'>0 0 0 0 -0 0</pose>
        <inertial>
          <pose>0 0 0 0 -0 0</pose>
          <mass>0.6</mass>
          <inertia>
            <ixx>0.0006</ixx>
            <ixy>0</ixy>
            <ixz>0</ixz>
            <iyy>0.0006</iyy>
            <iyz>0</iyz>
            <izz>0.0006</izz>
          </inertia>
        </inertial>
        <collision name='right_back_wheel_link_collision'>
          <pose>0 0 0 1.5708 -0 0</pose>
          <geometry>
            <cylinder>
              <length>0.04</length>
              <radius>0.05</radius>
            </cylinder>
          </geometry>
          <surface>
            <contact>
              <ode/>
            </contact>
            <friction>
              <ode>
                <mu>0.01</mu>
                <mu2>0.01</mu2>
              </ode>
              <torsional>
                <ode/>
              </torsional>
            </friction>
            <bounce/>
          </surface>
          <max_contacts>10</max_contacts>
        </collision>
        <visual name='right_back_wheel_link_visual'>
          <pose>0 0 0 1.5708 -0 0</pose>
          <geometry>
            <cylinder>
              <length>0.04</length>
              <radius>0.05</radius>
            </cylinder>
          </geometry>
          <material>
            <ambient>0.1764 0.4588 0.8509 1</ambient>
            <diffuse>0.1764 0.4588 0.8509 1</diffuse>
            <specular>0.1764 0.4588 0.8509 1</specular>
            <emissive>0 0 0 0</emissive>
            <script>
              <name>Gazebo/Black</name>
              <uri>file://media/materials/scripts/gazebo.material</uri>
            </script>
          </material>
        </visual>
        <self_collide>0</self_collide>
        <enable_wind>0</enable_wind>
        <kinematic>0</kinematic>
      </link>
      <joint name='right_front_wheel_joint' type='revolute'>
        <pose relative_to='base_link'>0.125 -0.15 0 0 -0 0</pose>
        <parent>base_link</parent>
        <child>right_front_wheel_link</child>
        <axis>
          <xyz>0 1 0</xyz>
          <limit>
            <lower>-1e+16</lower>
            <upper>1e+16</upper>
          </limit>
          <dynamics>
            <spring_reference>0</spring_reference>
            <spring_stiffness>0</spring_stiffness>
          </dynamics>
        </axis>
      </joint>
      <link name='right_front_wheel_link'>
        <pose relative_to='right_front_wheel_joint'>0 0 0 0 -0 0</pose>
        <inertial>
          <pose>0 0 0 0 -0 0</pose>
          <mass>0.6</mass>
          <inertia>
            <ixx>0.0006</ixx>
            <ixy>0</ixy>
            <ixz>0</ixz>
            <iyy>0.0006</iyy>
            <iyz>0</iyz>
            <izz>0.0006</izz>
          </inertia>
        </inertial>
        <collision name='right_front_wheel_link_collision'>
          <pose>0 0 0 1.5708 -0 0</pose>
          <geometry>
            <cylinder>
              <length>0.04</length>
              <radius>0.05</radius>
            </cylinder>
          </geometry>
          <surface>
            <contact>
              <ode/>
            </contact>
            <friction>
              <ode>
                <mu>0.01</mu>
                <mu2>0.01</mu2>
              </ode>
              <torsional>
                <ode/>
              </torsional>
            </friction>
            <bounce/>
          </surface>
          <max_contacts>10</max_contacts>
        </collision>
        <visual name='right_front_wheel_link_visual'>
          <pose>0 0 0 1.5708 -0 0</pose>
          <geometry>
            <cylinder>
              <length>0.04</length>
              <radius>0.05</radius>
            </cylinder>
          </geometry>
          <material>
            <ambient>0.1764 0.4588 0.8509 1</ambient>
            <diffuse>0.1764 0.4588 0.8509 1</diffuse>
            <specular>0.1764 0.4588 0.8509 1</specular>
            <emissive>0 0 0 0</emissive>
            <script>
              <name>Gazebo/Black</name>
              <uri>file://media/materials/scripts/gazebo.material</uri>
            </script>
          </material>
        </visual>
        <self_collide>0</self_collide>
        <enable_wind>0</enable_wind>
        <kinematic>0</kinematic>
      </link>
      <static>0</static>
      <plugin name='wheel_drive' filename='libgazebo_ros_planar_move.so'>
        <commandTopic>cmd_vel</commandTopic>
        <odometryTopic>odom</odometryTopic>
        <odometryFrame>odom</odometryFrame>
        <odometryRate>50.0</odometryRate>
        <robotBaseFram>base_link</robotBaseFram>
      </plugin>
      <pose>0 0 0 0 -0 0</pose>
    </model>
    <model name='cafe'>
      <static>1</static>
      <link name='link'>
        <collision name='main_floor'>
          <pose>-0.4 -0.75 0.0948 0 -0 0</pose>
          <geometry>
            <box>
              <size>9.38 22.63 0.19</size>
            </box>
          </geometry>
          <max_contacts>10</max_contacts>
          <surface>
            <contact>
              <ode/>
            </contact>
            <bounce/>
            <friction>
              <torsional>
                <ode/>
              </torsional>
              <ode/>
            </friction>
          </surface>
        </collision>
        <collision name='wall_1'>
          <pose>-5.03 0.53 1.415 0 -0 0</pose>
          <geometry>
            <box>
              <size>0.12 23.16 2.83</size>
            </box>
          </geometry>
          <max_contacts>10</max_contacts>
          <surface>
            <contact>
              <ode/>
            </contact>
            <bounce/>
            <friction>
              <torsional>
                <ode/>
              </torsional>
              <ode/>
            </friction>
          </surface>
        </collision>
        <collision name='wall_2'>
          <pose>4.24 -0.31 1.415 0 -0 0</pose>
          <geometry>
            <box>
              <size>0.12 21.48 2.83</size>
            </box>
          </geometry>
          <max_contacts>10</max_contacts>
          <surface>
            <contact>
              <ode/>
            </contact>
            <bounce/>
            <friction>
              <torsional>
                <ode/>
              </torsional>
              <ode/>
            </friction>
          </surface>
        </collision>
        <collision name='wall_3'>
          <pose>-1.48 7.43 1.415 0 -0 0</pose>
          <geometry>
            <box>
              <size>7.2 0.12 2.83</size>
            </box>
          </geometry>
          <max_contacts>10</max_contacts>
          <surface>
            <contact>
              <ode/>
            </contact>
            <bounce/>
            <friction>
              <torsional>
                <ode/>
              </torsional>
              <ode/>
            </friction>
          </surface>
        </collision>
        <collision name='wall_4'>
          <pose>2.09 8.9 1.435 0 -0 0</pose>
          <geometry>
            <box>
              <size>0.12 3.05 2.87</size>
            </box>
          </geometry>
          <max_contacts>10</max_contacts>
          <surface>
            <contact>
              <ode/>
            </contact>
            <bounce/>
            <friction>
              <torsional>
                <ode/>
              </torsional>
              <ode/>
            </friction>
          </surface>
        </collision>
        <collision name='wall_5'>
          <pose>3.155 10.4 1.435 0 -0 0</pose>
          <geometry>
            <box>
              <size>2.13 0.12 2.87</size>
            </box>
          </geometry>
          <max_contacts>10</max_contacts>
          <surface>
            <contact>
              <ode/>
            </contact>
            <bounce/>
            <friction>
              <torsional>
                <ode/>
              </torsional>
              <ode/>
            </friction>
          </surface>
        </collision>
        <collision name='wall_6'>
          <pose>0.615 -10.98 1.415 0 -0 0</pose>
          <geometry>
            <box>
              <size>7.36 0.15 2.83</size>
            </box>
          </geometry>
          <max_contacts>10</max_contacts>
          <surface>
            <contact>
              <ode/>
            </contact>
            <bounce/>
            <friction>
              <torsional>
                <ode/>
              </torsional>
              <ode/>
            </friction>
          </surface>
        </collision>
        <collision name='wall_7'>
          <pose>-4.62 -10.98 1.415 0 -0 0</pose>
          <geometry>
            <box>
              <size>0.93 0.15 2.83</size>
            </box>
          </geometry>
          <max_contacts>10</max_contacts>
          <surface>
            <contact>
              <ode/>
            </contact>
            <bounce/>
            <friction>
              <torsional>
                <ode/>
              </torsional>
              <ode/>
            </friction>
          </surface>
        </collision>
        <collision name='wall_8'>
          <pose>-3.61 -10.98 2.69 0 -0 0</pose>
          <geometry>
            <box>
              <size>1.09 0.15 0.28</size>
            </box>
          </geometry>
          <max_contacts>10</max_contacts>
          <surface>
            <contact>
              <ode/>
            </contact>
            <bounce/>
            <friction>
              <torsional>
                <ode/>
              </torsional>
              <ode/>
            </friction>
          </surface>
        </collision>
        <collision name='coke'>
          <pose>-4.385 0.26 0.95 0 -0 0</pose>
          <geometry>
            <box>
              <size>1.03 1.03 1.52</size>
            </box>
          </geometry>
          <max_contacts>10</max_contacts>
          <surface>
            <contact>
              <ode/>
            </contact>
            <bounce/>
            <friction>
              <torsional>
                <ode/>
              </torsional>
              <ode/>
            </friction>
          </surface>
        </collision>
        <visual name='visual'>
          <geometry>
            <mesh>
              <uri>model://cafe/meshes/cafe.dae</uri>
            </mesh>
          </geometry>
        </visual>
        <self_collide>0</self_collide>
        <enable_wind>0</enable_wind>
        <kinematic>0</kinematic>
      </link>
      <pose>-0.566429 0.517898 0 0 -0 0</pose>
    </model>
    <model name='ground_plane_0'>
      <static>1</static>
      <link name='link'>
        <collision name='collision'>
          <geometry>
            <plane>
              <normal>0 0 1</normal>
              <size>100 100</size>
            </plane>
          </geometry>
          <surface>
            <contact>
              <collide_bitmask>65535</collide_bitmask>
              <ode/>
            </contact>
            <friction>
              <ode>
                <mu>100</mu>
                <mu2>50</mu2>
              </ode>
              <torsional>
                <ode/>
              </torsional>
            </friction>
            <bounce/>
          </surface>
          <max_contacts>10</max_contacts>
        </collision>
        <visual name='visual'>
          <cast_shadows>0</cast_shadows>
          <geometry>
            <plane>
              <normal>0 0 1</normal>
              <size>100 100</size>
            </plane>
          </geometry>
          <material>
            <script>
              <uri>file://media/materials/scripts/gazebo.material</uri>
              <name>Gazebo/Grey</name>
            </script>
          </material>
        </visual>
        <self_collide>0</self_collide>
        <enable_wind>0</enable_wind>
        <kinematic>0</kinematic>
      </link>
      <pose>-0.741769 1.368 0 0 -0 0</pose>
    </model>
    <model name='unit_cylinder'>
      <pose>1.98067 -1.21652 0.5 0 -0 0</pose>
      <link name='link'>
        <inertial>
          <mass>1</mass>
          <inertia>
            <ixx>0.145833</ixx>
            <ixy>0</ixy>
            <ixz>0</ixz>
            <iyy>0.145833</iyy>
            <iyz>0</iyz>
            <izz>0.125</izz>
          </inertia>
          <pose>0 0 0 0 -0 0</pose>
        </inertial>
        <collision name='collision'>
          <geometry>
            <cylinder>
              <radius>0.5</radius>
              <length>1</length>
            </cylinder>
          </geometry>
          <max_contacts>10</max_contacts>
          <surface>
            <contact>
              <ode/>
            </contact>
            <bounce/>
            <friction>
              <torsional>
                <ode/>
              </torsional>
              <ode/>
            </friction>
          </surface>
        </collision>
        <visual name='visual'>
          <geometry>
            <cylinder>
              <radius>0.5</radius>
              <length>1</length>
            </cylinder>
          </geometry>
          <material>
            <script>
              <name>Gazebo/Grey</name>
              <uri>file://media/materials/scripts/gazebo.material</uri>
            </script>
          </material>
        </visual>
        <self_collide>0</self_collide>
        <enable_wind>0</enable_wind>
        <kinematic>0</kinematic>
      </link>
    </model>
    <model name='unit_box'>
      <pose>-0.826912 -1.44795 0.5 0 -0 0</pose>
      <link name='link'>
        <inertial>
          <mass>1</mass>
          <inertia>
            <ixx>0.166667</ixx>
            <ixy>0</ixy>
            <ixz>0</ixz>
            <iyy>0.166667</iyy>
            <iyz>0</iyz>
            <izz>0.166667</izz>
          </inertia>
          <pose>0 0 0 0 -0 0</pose>
        </inertial>
        <collision name='collision'>
          <geometry>
            <box>
              <size>1 1 1</size>
            </box>
          </geometry>
          <max_contacts>10</max_contacts>
          <surface>
            <contact>
              <ode/>
            </contact>
            <bounce/>
            <friction>
              <torsional>
                <ode/>
              </torsional>
              <ode/>
            </friction>
          </surface>
        </collision>
        <visual name='visual'>
          <geometry>
            <box>
              <size>1 1 1</size>
            </box>
          </geometry>
          <material>
            <script>
              <name>Gazebo/Grey</name>
              <uri>file://media/materials/scripts/gazebo.material</uri>
            </script>
          </material>
        </visual>
        <self_collide>0</self_collide>
        <enable_wind>0</enable_wind>
        <kinematic>0</kinematic>
      </link>
    </model>
    <model name='unit_box_0'>
      <pose>3.03781 1.46487 0.5 0 -0 0</pose>
      <link name='link'>
        <inertial>
          <mass>1</mass>
          <inertia>
            <ixx>0.166667</ixx>
            <ixy>0</ixy>
            <ixz>0</ixz>
            <iyy>0.166667</iyy>
            <iyz>0</iyz>
            <izz>0.166667</izz>
          </inertia>
          <pose>0 0 0 0 -0 0</pose>
        </inertial>
        <collision name='collision'>
          <geometry>
            <box>
              <size>1 1 1</size>
            </box>
          </geometry>
          <max_contacts>10</max_contacts>
          <surface>
            <contact>
              <ode/>
            </contact>
            <bounce/>
            <friction>
              <torsional>
                <ode/>
              </torsional>
              <ode/>
            </friction>
          </surface>
        </collision>
        <visual name='visual'>
          <geometry>
            <box>
              <size>1 1 1</size>
            </box>
          </geometry>
          <material>
            <script>
              <name>Gazebo/Grey</name>
              <uri>file://media/materials/scripts/gazebo.material</uri>
            </script>
          </material>
        </visual>
        <self_collide>0</self_collide>
        <enable_wind>0</enable_wind>
        <kinematic>0</kinematic>
      </link>
    </model>
    <model name='unit_sphere'>
      <pose>-0.101594 1.66237 0.5 0 -0 0</pose>
      <link name='link'>
        <inertial>
          <mass>1</mass>
          <inertia>
            <ixx>0.1</ixx>
            <ixy>0</ixy>
            <ixz>0</ixz>
            <iyy>0.1</iyy>
            <iyz>0</iyz>
            <izz>0.1</izz>
          </inertia>
          <pose>0 0 0 0 -0 0</pose>
        </inertial>
        <collision name='collision'>
          <geometry>
            <sphere>
              <radius>0.5</radius>
            </sphere>
          </geometry>
          <max_contacts>10</max_contacts>
          <surface>
            <contact>
              <ode/>
            </contact>
            <bounce/>
            <friction>
              <torsional>
                <ode/>
              </torsional>
              <ode/>
            </friction>
          </surface>
        </collision>
        <visual name='visual'>
          <geometry>
            <sphere>
              <radius>0.5</radius>
            </sphere>
          </geometry>
          <material>
            <script>
              <name>Gazebo/Grey</name>
              <uri>file://media/materials/scripts/gazebo.material</uri>
            </script>
          </material>
        </visual>
        <self_collide>0</self_collide>
        <enable_wind>0</enable_wind>
        <kinematic>0</kinematic>
      </link>
    </model>
    <model name='unit_cylinder_0'>
      <pose>-2.19757 -4.31696 0.5 0 -0 0</pose>
      <link name='link'>
        <inertial>
          <mass>1</mass>
          <inertia>
            <ixx>0.145833</ixx>
            <ixy>0</ixy>
            <ixz>0</ixz>
            <iyy>0.145833</iyy>
            <iyz>0</iyz>
            <izz>0.125</izz>
          </inertia>
          <pose>0 0 0 0 -0 0</pose>
        </inertial>
        <collision name='collision'>
          <geometry>
            <cylinder>
              <radius>0.5</radius>
              <length>1</length>
            </cylinder>
          </geometry>
          <max_contacts>10</max_contacts>
          <surface>
            <contact>
              <ode/>
            </contact>
            <bounce/>
            <friction>
              <torsional>
                <ode/>
              </torsional>
              <ode/>
            </friction>
          </surface>
        </collision>
        <visual name='visual'>
          <geometry>
            <cylinder>
              <radius>0.5</radius>
              <length>1</length>
            </cylinder>
          </geometry>
          <material>
            <script>
              <name>Gazebo/Grey</name>
              <uri>file://media/materials/scripts/gazebo.material</uri>
            </script>
          </material>
        </visual>
        <self_collide>0</self_collide>
        <enable_wind>0</enable_wind>
        <kinematic>0</kinematic>
      </link>
    </model>
    <model name='unit_box_1'>
      <pose>-4.63985 3.70652 0.5 0 -0 0</pose>
      <link name='link'>
        <inertial>
          <mass>1</mass>
          <inertia>
            <ixx>0.166667</ixx>
            <ixy>0</ixy>
            <ixz>0</ixz>
            <iyy>0.166667</iyy>
            <iyz>0</iyz>
            <izz>0.166667</izz>
          </inertia>
          <pose>0 0 0 0 -0 0</pose>
        </inertial>
        <collision name='collision'>
          <geometry>
            <box>
              <size>1 1 1</size>
            </box>
          </geometry>
          <max_contacts>10</max_contacts>
          <surface>
            <contact>
              <ode/>
            </contact>
            <bounce/>
            <friction>
              <torsional>
                <ode/>
              </torsional>
              <ode/>
            </friction>
          </surface>
        </collision>
        <visual name='visual'>
          <geometry>
            <box>
              <size>1 1 1</size>
            </box>
          </geometry>
          <material>
            <script>
              <name>Gazebo/Grey</name>
              <uri>file://media/materials/scripts/gazebo.material</uri>
            </script>
          </material>
        </visual>
        <self_collide>0</self_collide>
        <enable_wind>0</enable_wind>
        <kinematic>0</kinematic>
      </link>
    </model>
    <state world_name='default'>
      <sim_time>182 799000000</sim_time>
      <real_time>194 50108459</real_time>
      <wall_time>1692880137 119193875</wall_time>
      <iterations>182799</iterations>
      <model name='cafe'>
        <pose>-0.566429 0.517898 0 0 -0 0</pose>
        <scale>1 1 1</scale>
        <link name='link'>
          <pose>-0.566429 0.517898 0 0 -0 0</pose>
          <velocity>0 0 0 0 -0 0</velocity>
          <acceleration>0 0 0 0 -0 0</acceleration>
          <wrench>0 0 0 0 -0 0</wrench>
        </link>
      </model>
      <model name='ground_plane'>
        <pose>0 0 0 0 -0 0</pose>
        <scale>1 1 1</scale>
        <link name='link'>
          <pose>0 0 0 0 -0 0</pose>
          <velocity>0 0 0 0 -0 0</velocity>
          <acceleration>0 0 0 0 -0 0</acceleration>
          <wrench>0 0 0 0 -0 0</wrench>
        </link>
      </model>
      <model name='ground_plane_0'>
        <pose>-0.741769 1.368 0 0 -0 0</pose>
        <scale>1 1 1</scale>
        <link name='link'>
          <pose>-0.741769 1.368 0 0 -0 0</pose>
          <velocity>0 0 0 0 -0 0</velocity>
          <acceleration>0 0 0 0 -0 0</acceleration>
          <wrench>0 0 0 0 -0 0</wrench>
        </link>
      </model>
      <model name='pynqcar'>
        <pose>0.462556 -0.165543 0.3598 1.57095 -4e-06 -0.00915</pose>
        <scale>1 1 1</scale>
        <link name='base_link'>
          <pose>0.462556 -0.165543 0.3598 1.57095 -4e-06 -0.00915</pose>
          <velocity>9.2e-05 -5.9e-05 -0.007068 -0.002684 -0.001762 0.000164</velocity>
          <acceleration>-0.0017 0.003814 -9.79742 0.045745 0.010091 -0.013436</acceleration>
          <wrench>-0.00119 0.00267 -6.85819 0 -0 0</wrench>
        </link>
        <link name='left_back_wheel_link'>
          <pose>0.33756 -0.164422 0.5098 1.57095 1.5e-05 -0.136614</pose>
          <velocity>-0.000175 0.000322 -0.007291 -0.002681 -0.001764 0</velocity>
          <acceleration>0.000233 0.000686 -9.79227 0.047744 0.00533 1e-06</acceleration>
          <wrench>0.00014 0.000412 -5.87536 0 -0 0</wrench>
        </link>
        <link name='left_front_wheel_link'>
          <pose>0.58755 -0.16671 0.509801 1.57073 -0.000138 1.96361</pose>
          <velocity>-0.000179 0.000358 -0.006841 -0.002664 -0.001773 0</velocity>
          <acceleration>-0.000509 -0.002946 -9.79456 0.034216 -0.000277 0</acceleration>
          <wrench>-0.000305 -0.001768 -5.87674 0 -0 0</wrench>
        </link>
        <link name='right_back_wheel_link'>
          <pose>0.337562 -0.164377 0.2098 1.57065 3.9e-05 -2.98475</pose>
          <velocity>0.000349 -0.000467 -0.007323 -0.001681 0.000884 -0.009008</velocity>
          <acceleration>0.015247 -0.005789 -9.79894 -0.121931 1.01263 0.000149</acceleration>
          <wrench>0.009148 -0.003473 -5.87936 0 -0 0</wrench>
        </link>
        <link name='right_front_wheel_link'>
          <pose>0.587551 -0.166664 0.209801 1.57066 6.8e-05 -2.69197</pose>
          <velocity>0.000354 -0.000452 -0.006804 -0.002652 -0.0025 -0.011936</velocity>
          <acceleration>-0.012987 0.003599 -9.81724 2.99258 0.021502 3.14111</acceleration>
          <wrench>-0.007792 0.00216 -5.89035 0 -0 0</wrench>
        </link>
      </model>
      <model name='unit_box'>
        <pose>-0.826912 -1.44795 0.6898 -0 -0 -0</pose>
        <scale>1 1 1</scale>
        <link name='link'>
          <pose>-0.826912 -1.44795 0.6898 -0 -0 -0</pose>
          <velocity>0 0 0 0 -0 0</velocity>
          <acceleration>-0 0 0 0 -0 0</acceleration>
          <wrench>-0 0 0 0 -0 0</wrench>
        </link>
      </model>
      <model name='unit_box_0'>
        <pose>3.03781 1.46487 0.6898 -0 -0 -0</pose>
        <scale>1 1 1</scale>
        <link name='link'>
          <pose>3.03781 1.46487 0.6898 -0 -0 -0</pose>
          <velocity>0 0 0 0 -0 0</velocity>
          <acceleration>0 -0 0 0 -0 0</acceleration>
          <wrench>0 -0 0 0 -0 0</wrench>
        </link>
      </model>
      <model name='unit_box_1'>
        <pose>-4.63985 3.70652 0.6898 -0 -0 -0</pose>
        <scale>1 1 1</scale>
        <link name='link'>
          <pose>-4.63985 3.70652 0.6898 -0 -0 -0</pose>
          <velocity>0 0 0 0 -0 0</velocity>
          <acceleration>-0 0 0 0 -0 0</acceleration>
          <wrench>-0 0 0 0 -0 0</wrench>
        </link>
      </model>
      <model name='unit_cylinder'>
        <pose>1.98067 -1.21651 0.6898 0 -0 1.6e-05</pose>
        <scale>1 1 1</scale>
        <link name='link'>
          <pose>1.98067 -1.21651 0.6898 0 -0 1.6e-05</pose>
          <velocity>0 0 0 0 -0 0</velocity>
          <acceleration>3e-06 4e-06 19.6 -8e-06 5e-06 0</acceleration>
          <wrench>3e-06 4e-06 19.6 0 -0 0</wrench>
        </link>
      </model>
      <model name='unit_cylinder_0'>
        <pose>-2.19759 -4.31696 0.6898 0 -0 -1.5e-05</pose>
        <scale>1 1 1</scale>
        <link name='link'>
          <pose>-2.19759 -4.31696 0.6898 0 -0 -1.5e-05</pose>
          <velocity>0 0 0 0 -0 0</velocity>
          <acceleration>-5e-06 -1e-06 19.6 2e-06 -9e-06 0</acceleration>
          <wrench>-5e-06 -1e-06 19.6 0 -0 0</wrench>
        </link>
      </model>
      <model name='unit_sphere'>
        <pose>-0.101594 1.66237 0.6898 0 -0 0</pose>
        <scale>1 1 1</scale>
        <link name='link'>
          <pose>-0.101594 1.66237 0.6898 0 -0 0</pose>
          <velocity>0 0 0 0 -0 0</velocity>
          <acceleration>-0 0 0 0 -0 0</acceleration>
          <wrench>-0 0 0 0 -0 0</wrench>
        </link>
      </model>
      <light name='sun'>
        <pose>0 0 10 0 -0 0</pose>
      </light>
    </state>
    <gui fullscreen='0'>
      <camera name='user_camera'>
        <pose>5.46086 -5.48456 13.672 0 1.02343 2.11979</pose>
        <view_controller>orbit</view_controller>
        <projection_type>perspective</projection_type>
      </camera>
    </gui>
  </world>
</sdf>
